<?xml version="1.0" ?>
<mujoco>
  <compiler angle="radian"/>
  <option collision="predefined"/>
  <default>
    <joint limited="true" range="-0.5235987755982988 0.5235987755982988" damping="0.1" armature="0.001"/>
    <position ctrllimited="true" ctrlrange="-0.5235987755982988 0.5235987755982988" kp="1."/>
    <geom rgba="1 1 1 1"/>
  </default>
  <worldbody>
    <body name="toplevel_body1">
      <body name="toplevel_body2">
        <joint name="elbow_pitch" type="hinge" axis="1 0 0" range="-0.6981317007977318 0.6981317007977318" damping="3"/>
        <body name="forearm">
          <geom name="forearm_geom" type="capsule" fromto="0 0 0 0 0.3 0" size="0.02"/>
          <body name="wrist" pos="0 0.3 0">
            <joint name="wrist_pitch" type="hinge" axis="1 0 0" range="-0.6981317007977318 0.6981317007977318" damping="3"/>
            <joint name="wrist_yaw" type="hinge" axis="0 1 0" range="0 1.5707963267948966" damping="3"/>
            <body name="root" pos="0 0 0">
              <geom name="root_geom" type="capsule" fromto="0 0 0 0.0 0.03 0.0" size="0.008"/>
              <body name="middle2index" pos="0.0 0.03 0.0">
                <geom name="middle2index_geom" type="capsule" fromto="0 0 0 -0.013 0.001 0.0" size="0.008"/>
                <body name="index2thumb" pos="-0.013 0.001 0.0">
                  <geom name="index2thumb_geom" type="capsule" fromto="0 0 0 -0.00467199999999999 -0.013741599999999998 0.0" size="0.008"/>
                  <body name="thumb_t" pos="-0.00467199999999999 -0.013741599999999998 0.0">
                    <geom name="thumb_t_geom" type="capsule" fromto="0 0 0 -0.004538000000000003 0.007398599999999999 0.0" size="0.008"/>
                    <joint name="thumb_t_joint" type="hinge" axis="0.3 1.0 0.3" range="-1.5 0"/>
                    <body name="thumb_mc" pos="-0.004538000000000003 0.007398599999999999 0.0">
                      <geom name="thumb_mc_geom" type="capsule" fromto="0 0 0 -0.022690000000000016 0.036993 0.0" size="0.008"/>
                      <joint name="thumb_mc_joint" type="hinge" axis="0.3 -0.5 1.0" range="-0.2 1.2"/>
                      <body name="thumb_pp" pos="-0.022690000000000016 0.036993 0.0">
                        <geom name="thumb_pp_geom" type="capsule" fromto="0 0 0 -0.013099999999999994 0.030350000000000002 0.0" size="0.008"/>
                        <joint name="thumb_pp_joint" type="hinge" axis="0.9181248990731756 0.3962911425983062 0.8" range="-1.5 0"/>
                        <body name="thumb_dp" pos="-0.013099999999999994 0.030350000000000002 0.0">
                          <geom name="thumb_dp_geom" type="capsule" fromto="0 0 0 -0.003 0.022 0.0" size="0.008"/>
                          <joint name="thumb_dp_joint" type="hinge" axis="0.990830168044299 0.1351132047333135 0.8" range="-1.5 0"/>
                          <body name="fingertip_0" pos="-0.003 0.022 0.0">
                            <geom name="fingertip_0_geom" type="sphere" size="0.00808" rgba="0.6 0.6 0.6 1"/>
                          </body>
                        </body>
                      </body>
                    </body>
                  </body>
                </body>
                <body name="index_mc" pos="-0.013 0.001 0.0">
                  <geom name="index_mc_geom" type="capsule" fromto="0 0 0 -0.018999999999999996 0.066 0.0" size="0.008"/>
                  <body name="index_pp" pos="-0.018999999999999996 0.066 0.0">
                    <geom name="index_pp_geom" type="capsule" fromto="0 0 0 -0.005 0.043 0.0" size="0.008"/>
                    <joint name="index_pp_joint" type="hinge" axis="0.9933073803012535 0.11550085817456437 0.0" range="-1.5 0"/>
                    <body name="index_mp" pos="-0.005 0.043 0.0">
                      <geom name="index_mp_geom" type="capsule" fromto="0 0 0 -0.001 0.027 0.0" size="0.008"/>
                      <joint name="index_mp_joint" type="hinge" axis="0.9993148337667671 0.037011660509880265 0.0" range="-1.5 0"/>
                      <body name="index_dp" pos="-0.001 0.027 0.0">
                        <geom name="index_dp_geom" type="capsule" fromto="0 0 0 0.001 0.019 0.0" size="0.008"/>
                        <joint name="index_dp_joint" type="hinge" axis="0.9986178293325098 -0.052558833122763673 0.0" range="-1.5 0"/>
                        <body name="fingertip_1" pos="0.001 0.019 0.0">
                          <geom name="fingertip_1_geom" type="sphere" size="0.00808" rgba="0.6 0.6 0.6 1"/>
                        </body>
                      </body>
                    </body>
                  </body>
                </body>
              </body>
              <body name="middle2ring" pos="0.0 0.03 0.0">
                <geom name="middle2ring_geom" type="capsule" fromto="0 0 0 0.013 0.0 0.0" size="0.008"/>
                <body name="ring2pinky" pos="0.013 0.0 0.0">
                  <geom name="ring2pinky_geom" type="capsule" fromto="0 0 0 0.012 0.001 0.0" size="0.008"/>
                  <body name="pinky_mc" pos="0.012 0.001 0.0">
                    <geom name="pinky_mc_geom" type="capsule" fromto="0 0 0 0.007 0.056 0.0" size="0.008"/>
                    <body name="pinky_pp" pos="0.007 0.056 0.0">
                      <geom name="pinky_pp_geom" type="capsule" fromto="0 0 0 0.002 0.037 0.0" size="0.008"/>
                      <joint name="pinky_pp_joint" type="hinge" axis="0.9985422732775083 -0.05397525801500046 0.0" range="-1.5 0"/>
                      <body name="pinky_mp" pos="0.002 0.037 0.0">
                        <geom name="pinky_mp_geom" type="capsule" fromto="0 0 0 0.001 0.022 0.0" size="0.008"/>
                        <joint name="pinky_mp_joint" type="hinge" axis="0.9989685402102996 -0.045407660918649985 0.0" range="-1.5 0"/>
                        <body name="pinky_dp" pos="0.001 0.022 0.0">
                          <geom name="pinky_dp_geom" type="capsule" fromto="0 0 0 -0.001 0.018 0.0" size="0.008"/>
                          <joint name="pinky_dp_joint" type="hinge" axis="0.9984603532054124 0.05547001962252292 0.0" range="-1.5 0"/>
                          <body name="fingertip_2" pos="-0.001 0.018 0.0">
                            <geom name="fingertip_2_geom" type="sphere" size="0.00808" rgba="0.6 0.6 0.6 1"/>
                          </body>
                        </body>
                      </body>
                    </body>
                  </body>
                </body>
                <body name="ring_mc" pos="0.013 0.0 0.0">
                  <geom name="ring_mc_geom" type="capsule" fromto="0 0 0 -0.001 0.063 0.0" size="0.008"/>
                  <body name="ring_pp" pos="-0.001 0.063 0.0">
                    <geom name="ring_pp_geom" type="capsule" fromto="0 0 0 -0.001 0.044 0.0" size="0.008"/>
                    <joint name="ring_pp_joint" type="hinge" axis="0.9997418355449428 0.022721405353294154 0.0" range="-1.5 0"/>
                    <body name="ring_mp" pos="-0.001 0.044 0.0">
                      <geom name="ring_mp_geom" type="capsule" fromto="0 0 0 -0.002 0.031 0.0" size="0.008"/>
                      <joint name="ring_mp_joint" type="hinge" axis="0.9979253089684582 0.06438227799796505 0.0" range="-1.5 0"/>
                      <body name="ring_dp" pos="-0.002 0.031 0.0">
                        <geom name="ring_dp_geom" type="capsule" fromto="0 0 0 0.0 0.02 0.0" size="0.008"/>
                        <joint name="ring_dp_joint" type="hinge" axis="1.0 -0.0 0.0" range="-1.5 0"/>
                        <body name="fingertip_3" pos="0.0 0.02 0.0">
                          <geom name="fingertip_3_geom" type="sphere" size="0.00808" rgba="0.6 0.6 0.6 1"/>
                        </body>
                      </body>
                    </body>
                  </body>
                </body>
              </body>
              <body name="middle_mc" pos="0.0 0.03 0.0">
                <geom name="middle_mc_geom" type="capsule" fromto="0 0 0 -0.009 0.069 0.0" size="0.008"/>
                <body name="middle_pp" pos="-0.009 0.069 0.0">
                  <geom name="middle_pp_geom" type="capsule" fromto="0 0 0 -0.005 0.045 0.0" size="0.008"/>
                  <joint name="middle_pp_joint" type="hinge" axis="0.9938837346736189 0.11043152607484656 0.0" range="-1.5 0"/>
                  <body name="middle_mp" pos="-0.005 0.045 0.0">
                    <geom name="middle_mp_geom" type="capsule" fromto="0 0 0 0.0 0.032 0.0" size="0.008"/>
                    <joint name="middle_mp_joint" type="hinge" axis="1.0 -0.0 0.0" range="-1.5 0"/>
                    <body name="middle_dp" pos="0.0 0.032 0.0">
                      <geom name="middle_dp_geom" type="capsule" fromto="0 0 0 0.0 0.021 0.0" size="0.008"/>
                      <joint name="middle_dp_joint" type="hinge" axis="1.0 -0.0 0.0" range="-1.5 0"/>
                      <body name="fingertip_4" pos="0.0 0.021 0.0">
                        <geom name="fingertip_4_geom" type="sphere" size="0.00808" rgba="0.6 0.6 0.6 1"/>
                      </body>
                    </body>
                  </body>
                </body>
              </body>
            </body>
          </body>
        </body>
      </body>
    </body>
  </worldbody>
  <actuator>
    <position name="elbow_pitch" joint="elbow_pitch" ctrlrange="-0.6981317007977318 0.6981317007977318" kp="30."/>
    <position name="wrist_pitch" joint="wrist_pitch" ctrlrange="-0.6981317007977318 0.6981317007977318" kp="30."/>
    <position name="wrist_yaw" joint="wrist_yaw" ctrlrange="0 1.5707963267948966" kp="30."/>
    <position name="thumb_t_joint" joint="thumb_t_joint" ctrlrange="-1.5 0"/>
    <position name="thumb_mc_joint" joint="thumb_mc_joint" ctrlrange="-0.2 1.2"/>
    <position name="thumb_pp_joint" joint="thumb_pp_joint" ctrlrange="-1.5 0"/>
    <position name="thumb_dp_joint" joint="thumb_dp_joint" ctrlrange="-1.5 0"/>
    <position name="index_pp_joint" joint="index_pp_joint" ctrlrange="-1.5 0"/>
    <position name="index_mp_joint" joint="index_mp_joint" ctrlrange="-1.5 0"/>
    <position name="index_dp_joint" joint="index_dp_joint" ctrlrange="-1.5 0"/>
    <position name="pinky_pp_joint" joint="pinky_pp_joint" ctrlrange="-1.5 0"/>
    <position name="pinky_mp_joint" joint="pinky_mp_joint" ctrlrange="-1.5 0"/>
    <position name="pinky_dp_joint" joint="pinky_dp_joint" ctrlrange="-1.5 0"/>
    <position name="ring_pp_joint" joint="ring_pp_joint" ctrlrange="-1.5 0"/>
    <position name="ring_mp_joint" joint="ring_mp_joint" ctrlrange="-1.5 0"/>
    <position name="ring_dp_joint" joint="ring_dp_joint" ctrlrange="-1.5 0"/>
    <position name="middle_pp_joint" joint="middle_pp_joint" ctrlrange="-1.5 0"/>
    <position name="middle_mp_joint" joint="middle_mp_joint" ctrlrange="-1.5 0"/>
    <position name="middle_dp_joint" joint="middle_dp_joint" ctrlrange="-1.5 0"/>
  </actuator>
</mujoco>
